[23/Mar/2019 18:07:17] "GET / HTTP/1.1" 200 3998
[23/Mar/2019 18:07:17] "GET /static/home/main.css HTTP/1.1" 304 0
[23/Mar/2019 18:07:17] "GET /media/chicago_skyline.jpg HTTP/1.1" 304 0
[23/Mar/2019 18:07:20] "GET /serviceRequest/ HTTP/1.1" 200 191276
[23/Mar/2019 18:09:27] "GET /serviceRequest/ HTTP/1.1" 200 190835
[23/Mar/2019 22:42:20] "GET /serviceRequest HTTP/1.1" 301 0
[23/Mar/2019 22:42:20] "GET /serviceRequest/ HTTP/1.1" 200 190745
[23/Mar/2019 22:42:20] "GET /static/home/main.css HTTP/1.1" 200 1092
Not Found: /favicon.ico
[23/Mar/2019 22:42:21] "GET /favicon.ico HTTP/1.1" 404 2891
[23/Mar/2019 22:42:24] "GET / HTTP/1.1" 200 3908
[23/Mar/2019 22:42:24] "GET /media/chicago_skyline.jpg HTTP/1.1" 200 167062
[23/Mar/2019 22:42:28] "GET / HTTP/1.1" 200 3908
[23/Mar/2019 22:42:31] "GET / HTTP/1.1" 200 3908
[23/Mar/2019 22:42:32] "GET /login/ HTTP/1.1" 200 3376
[23/Mar/2019 22:42:41] "GET /register/ HTTP/1.1" 200 4609
[23/Mar/2019 22:42:48] "GET /login/ HTTP/1.1" 200 3376
[23/Mar/2019 22:42:51] "GET /register/ HTTP/1.1" 200 4609
[23/Mar/2019 22:42:52] "GET /login/ HTTP/1.1" 200 3376
[23/Mar/2019 22:42:53] "GET / HTTP/1.1" 200 3908
[23/Mar/2019 22:42:55] "GET / HTTP/1.1" 200 3908
[23/Mar/2019 22:42:57] "GET /login/ HTTP/1.1" 200 3376
[23/Mar/2019 22:45:21] "GET / HTTP/1.1" 200 3908
[23/Mar/2019 22:45:26] "GET /register/ HTTP/1.1" 200 4609
[23/Mar/2019 22:45:27] "GET /login/ HTTP/1.1" 200 3376
[23/Mar/2019 22:45:29] "GET / HTTP/1.1" 200 3908
[23/Mar/2019 22:45:32] "GET /login/ HTTP/1.1" 200 3376
[23/Mar/2019 22:45:35] "GET /register/ HTTP/1.1" 200 4609
[23/Mar/2019 22:45:38] "GET /login/ HTTP/1.1" 200 3376
[23/Mar/2019 22:45:39] "GET / HTTP/1.1" 200 3908
[23/Mar/2019 22:46:17] "GET / HTTP/1.1" 200 3908
Not Found: /favicon.ico
[23/Mar/2019 22:46:17] "GET /favicon.ico HTTP/1.1" 404 2891
[23/Mar/2019 22:48:14] "GET / HTTP/1.1" 200 3908
Not Found: /favicon.ico
[23/Mar/2019 22:48:14] "GET /favicon.ico HTTP/1.1" 404 2891
[23/Mar/2019 22:48:21] "GET / HTTP/1.1" 200 3908
[23/Mar/2019 22:48:24] "GET / HTTP/1.1" 200 3908
[23/Mar/2019 22:48:26] "GET /login/ HTTP/1.1" 200 3376
[23/Mar/2019 22:48:27] "GET /register/ HTTP/1.1" 200 4609
[25/Mar/2019 18:39:37] "GET /serviceRequest HTTP/1.1" 301 0
[25/Mar/2019 18:39:38] "GET /serviceRequest/ HTTP/1.1" 200 190745
[25/Mar/2019 18:39:38] "GET /static/home/main.css HTTP/1.1" 304 0
Not Found: /favicon.ico
[25/Mar/2019 18:39:38] "GET /favicon.ico HTTP/1.1" 404 2891
[25/Mar/2019 18:39:41] "GET /login/ HTTP/1.1" 200 3376
[25/Mar/2019 18:39:43] "GET / HTTP/1.1" 200 3908
[25/Mar/2019 18:39:43] "GET /media/chicago_skyline.jpg HTTP/1.1" 200 167062
[25/Mar/2019 18:39:46] "GET / HTTP/1.1" 200 3908
[25/Mar/2019 19:22:54] "GET /admin HTTP/1.1" 301 0
[25/Mar/2019 19:22:54] "GET /admin/ HTTP/1.1" 302 0
[25/Mar/2019 19:22:54] "GET /admin/login/?next=/admin/ HTTP/1.1" 200 1824
[25/Mar/2019 19:22:54] "GET /static/admin/css/base.css HTTP/1.1" 200 16225
[25/Mar/2019 19:22:54] "GET /static/admin/css/login.css HTTP/1.1" 200 1203
[25/Mar/2019 19:22:54] "GET /static/admin/css/responsive.css HTTP/1.1" 200 17976
[25/Mar/2019 19:22:55] "GET /static/admin/css/fonts.css HTTP/1.1" 200 423
[25/Mar/2019 19:22:55] "GET /static/admin/fonts/Roboto-Light-webfont.woff HTTP/1.1" 200 81348
[25/Mar/2019 19:22:55] "GET /static/admin/fonts/Roboto-Regular-webfont.woff HTTP/1.1" 200 80304
[25/Mar/2019 19:22:59] "POST /admin/login/?next=/admin/ HTTP/1.1" 302 0
[25/Mar/2019 19:22:59] "GET /admin/ HTTP/1.1" 200 4464
[25/Mar/2019 19:22:59] "GET /static/admin/css/dashboard.css HTTP/1.1" 200 412
[25/Mar/2019 19:22:59] "GET /static/admin/img/icon-addlink.svg HTTP/1.1" 200 331
[25/Mar/2019 19:22:59] "GET /static/admin/img/icon-changelink.svg HTTP/1.1" 200 380
[25/Mar/2019 19:22:59] "GET /static/admin/fonts/Roboto-Bold-webfont.woff HTTP/1.1" 200 82564
[25/Mar/2019 19:23:01] "GET /admin/auth/user/ HTTP/1.1" 200 6614
[25/Mar/2019 19:23:01] "GET /static/admin/css/changelists.css HTTP/1.1" 200 6170
[25/Mar/2019 19:23:01] "GET /admin/jsi18n/ HTTP/1.1" 200 3185
[25/Mar/2019 19:23:01] "GET /static/admin/js/jquery.init.js HTTP/1.1" 200 363
[25/Mar/2019 19:23:01] "GET /static/admin/js/core.js HTTP/1.1" 200 7135
[25/Mar/2019 19:23:01] "GET /static/admin/js/admin/RelatedObjectLookups.js HTTP/1.1" 200 6918
[25/Mar/2019 19:23:01] "GET /static/admin/js/actions.js HTTP/1.1" 200 6538
[25/Mar/2019 19:23:01] "GET /static/admin/js/urlify.js HTTP/1.1" 200 8972
[25/Mar/2019 19:23:01] "GET /static/admin/js/prepopulate.js HTTP/1.1" 200 1530
[25/Mar/2019 19:23:01] "GET /static/admin/js/vendor/jquery/jquery.js HTTP/1.1" 200 271751
[25/Mar/2019 19:23:01] "GET /static/admin/img/search.svg HTTP/1.1" 200 458
[25/Mar/2019 19:23:01] "GET /static/admin/img/icon-yes.svg HTTP/1.1" 200 436
[25/Mar/2019 19:23:01] "GET /static/admin/js/vendor/xregexp/xregexp.js HTTP/1.1" 200 128820
[25/Mar/2019 19:23:01] "GET /static/admin/img/tooltag-add.svg HTTP/1.1" 200 331
[25/Mar/2019 19:23:01] "GET /static/admin/img/sorting-icons.svg HTTP/1.1" 200 1097
[25/Mar/2019 19:23:08] "GET /admin/ HTTP/1.1" 200 4464
[25/Mar/2019 19:23:10] "GET / HTTP/1.1" 200 3998
[25/Mar/2019 19:23:10] "GET /static/home/main.css HTTP/1.1" 200 1092
[25/Mar/2019 19:23:10] "GET /media/chicago_skyline.jpg HTTP/1.1" 200 167062
[25/Mar/2019 19:23:15] "GET /logout/ HTTP/1.1" 200 2299
[25/Mar/2019 19:23:16] "GET /register/ HTTP/1.1" 200 4609
[25/Mar/2019 19:23:26] "POST /register/ HTTP/1.1" 302 0
[25/Mar/2019 19:23:26] "GET /login/ HTTP/1.1" 200 3376
[25/Mar/2019 19:23:31] "POST /login/ HTTP/1.1" 302 0
[25/Mar/2019 19:23:31] "GET / HTTP/1.1" 200 3998
[25/Mar/2019 19:23:35] "GET /profile/ HTTP/1.1" 200 6906
[25/Mar/2019 19:23:35] "GET /media/default.jpg HTTP/1.1" 200 7199
[25/Mar/2019 19:23:36] "GET /logout/ HTTP/1.1" 200 2299
[25/Mar/2019 19:30:29] "GET /serviceRequest/ HTTP/1.1" 200 190745
[25/Mar/2019 19:36:16] "GET / HTTP/1.1" 200 3998
[25/Mar/2019 19:36:16] "GET /static/home/main.css HTTP/1.1" 200 1092
[25/Mar/2019 19:36:16] "GET /media/chicago_skyline.jpg HTTP/1.1" 200 167062
[25/Mar/2019 19:36:38] "GET /logout/ HTTP/1.1" 200 2299
[25/Mar/2019 19:36:52] "GET /serviceRequest HTTP/1.1" 301 0
[25/Mar/2019 19:36:52] "GET /serviceRequest/ HTTP/1.1" 302 0
[25/Mar/2019 19:36:52] "GET /login/?next=/serviceRequest/ HTTP/1.1" 200 3376
[25/Mar/2019 19:36:55] "GET /logout/ HTTP/1.1" 200 2299
Performing system checks...

System check identified no issues (0 silenced).
March 25, 2019 - 19:36:11
Django version 2.1.7, using settings 'teamHawkeye.settings'
Starting development server at http://sp19-cs411-12.cs.illinois.edu:8000/
Quit the server with CONTROL-C.
[25/Mar/2019 19:37:41] "GET / HTTP/1.1" 200 3908
[25/Mar/2019 19:37:41] "GET /static/home/main.css HTTP/1.1" 200 1092
[25/Mar/2019 19:37:41] "GET /media/chicago_skyline.jpg HTTP/1.1" 200 167062
Not Found: /favicon.ico
[25/Mar/2019 19:37:42] "GET /favicon.ico HTTP/1.1" 404 2891
Not Found: /servicerequest
[25/Mar/2019 19:37:53] "GET /servicerequest HTTP/1.1" 404 2900
[25/Mar/2019 19:37:54] "GET /login/ HTTP/1.1" 200 3376
[25/Mar/2019 19:38:02] "GET /serviceRequest/ HTTP/1.1" 302 0
[25/Mar/2019 19:38:02] "GET /login/?next=/serviceRequest/ HTTP/1.1" 200 3376
[25/Mar/2019 19:38:03] "GET /serviceRequest HTTP/1.1" 301 0
[25/Mar/2019 19:38:03] "GET /serviceRequest/ HTTP/1.1" 302 0
[25/Mar/2019 19:38:03] "GET /login/?next=/serviceRequest/ HTTP/1.1" 200 3376
Not Found: /serviceRequests/SRHomepage.html
[25/Mar/2019 19:38:03] "GET /serviceRequests/SRHomepage.html HTTP/1.1" 404 2951
[25/Mar/2019 19:38:07] "GET / HTTP/1.1" 200 3908
[25/Mar/2019 19:38:08] "GET / HTTP/1.1" 200 3908
[25/Mar/2019 19:38:09] "GET /login/ HTTP/1.1" 200 3376
[25/Mar/2019 19:38:10] "GET /register/ HTTP/1.1" 200 4609
[25/Mar/2019 19:38:12] "GET /login/ HTTP/1.1" 200 3376
[25/Mar/2019 19:38:13] "GET / HTTP/1.1" 200 3908
[25/Mar/2019 19:38:13] "GET / HTTP/1.1" 200 3908
Not Found: /deleteRequest
[25/Mar/2019 19:38:15] "GET /deleteRequest HTTP/1.1" 404 2897
[25/Mar/2019 19:38:15] "GET / HTTP/1.1" 200 3908
[25/Mar/2019 19:38:16] "GET /login/ HTTP/1.1" 200 3376
[25/Mar/2019 19:38:18] "GET /login/ HTTP/1.1" 200 3376
[25/Mar/2019 19:38:19] "GET /register/ HTTP/1.1" 200 4609
[25/Mar/2019 19:38:19] "GET /register/ HTTP/1.1" 200 4609
[25/Mar/2019 19:38:21] "GET /login/ HTTP/1.1" 200 3376
[25/Mar/2019 19:38:22] "GET / HTTP/1.1" 200 3908
[25/Mar/2019 19:38:24] "GET / HTTP/1.1" 200 3908
[25/Mar/2019 19:38:27] "GET /login/ HTTP/1.1" 200 3376
Not Found: /createRequest
[25/Mar/2019 19:38:28] "GET /createRequest HTTP/1.1" 404 2897
Not Found: /createRequest.html
[25/Mar/2019 19:38:30] "GET /createRequest.html HTTP/1.1" 404 2912
[25/Mar/2019 19:38:35] "GET /register HTTP/1.1" 301 0
[25/Mar/2019 19:38:35] "GET /register/ HTTP/1.1" 200 4609
[25/Mar/2019 19:38:41] "POST /register/ HTTP/1.1" 302 0
[25/Mar/2019 19:38:41] "GET /login/ HTTP/1.1" 200 3376
[25/Mar/2019 19:38:48] "POST /login/ HTTP/1.1" 302 0
[25/Mar/2019 19:38:48] "GET / HTTP/1.1" 200 3998
[25/Mar/2019 19:38:50] "GET /serviceRequest/ HTTP/1.1" 200 190835
[25/Mar/2019 19:39:06] "GET /serviceRequest/?page=2 HTTP/1.1" 200 191125
[25/Mar/2019 19:39:15] "GET /serviceRequest/?page=1 HTTP/1.1" 200 190835
[25/Mar/2019 19:39:39] "GET /register/ HTTP/1.1" 200 4609
[25/Mar/2019 19:46:40] "POST /register/ HTTP/1.1" 200 5024
[25/Mar/2019 19:47:02] "POST /register/ HTTP/1.1" 200 5024
[25/Mar/2019 19:47:22] "POST /register/ HTTP/1.1" 302 0
[25/Mar/2019 19:47:22] "GET /login/ HTTP/1.1" 200 3376
[25/Mar/2019 19:47:42] "POST /login/ HTTP/1.1" 200 3552
[25/Mar/2019 20:07:43] "GET /register/ HTTP/1.1" 200 4609
[25/Mar/2019 20:08:10] "POST /register/ HTTP/1.1" 200 5009
[25/Mar/2019 20:08:22] "POST /register/ HTTP/1.1" 200 4881
[25/Mar/2019 20:08:32] "POST /register/ HTTP/1.1" 200 4763
[25/Mar/2019 20:08:49] "POST /register/ HTTP/1.1" 302 0
[25/Mar/2019 20:08:49] "GET /login/ HTTP/1.1" 200 3376
[25/Mar/2019 20:08:58] "POST /login/ HTTP/1.1" 302 0
[25/Mar/2019 20:08:58] "GET / HTTP/1.1" 200 3998
[25/Mar/2019 20:09:01] "GET /serviceRequest/ HTTP/1.1" 200 190835
[25/Mar/2019 20:09:10] "GET /serviceRequest/ HTTP/1.1" 200 190835
Internal Server Error: /serviceRequest/53097/
Traceback (most recent call last):
  File "/usr/lib64/python3.6/site-packages/django/core/handlers/exception.py", line 34, in inner
    response = get_response(request)
  File "/usr/lib64/python3.6/site-packages/django/core/handlers/base.py", line 126, in _get_response
    response = self.process_exception_by_middleware(e, request)
  File "/usr/lib64/python3.6/site-packages/django/core/handlers/base.py", line 124, in _get_response
    response = wrapped_callback(request, *callback_args, **callback_kwargs)
  File "/usr/lib64/python3.6/site-packages/django/views/generic/base.py", line 68, in view
    return self.dispatch(request, *args, **kwargs)
  File "/usr/lib64/python3.6/site-packages/django/contrib/auth/mixins.py", line 52, in dispatch
    return super().dispatch(request, *args, **kwargs)
  File "/usr/lib64/python3.6/site-packages/django/contrib/auth/mixins.py", line 106, in dispatch
    user_test_result = self.get_test_func()()
  File "/usr/lib64/python3.6/site-packages/django/contrib/auth/mixins.py", line 96, in test_func
    '{0} is missing the implementation of the test_func() method.'.format(self.__class__.__name__)
NotImplementedError: srDetailView is missing the implementation of the test_func() method.
[25/Mar/2019 20:09:13] "GET /serviceRequest/53097/ HTTP/1.1" 500 81591
Internal Server Error: /serviceRequest/53097/
Traceback (most recent call last):
  File "/usr/lib64/python3.6/site-packages/django/core/handlers/exception.py", line 34, in inner
    response = get_response(request)
  File "/usr/lib64/python3.6/site-packages/django/core/handlers/base.py", line 126, in _get_response
    response = self.process_exception_by_middleware(e, request)
  File "/usr/lib64/python3.6/site-packages/django/core/handlers/base.py", line 124, in _get_response
    response = wrapped_callback(request, *callback_args, **callback_kwargs)
  File "/usr/lib64/python3.6/site-packages/django/views/generic/base.py", line 68, in view
    return self.dispatch(request, *args, **kwargs)
  File "/usr/lib64/python3.6/site-packages/django/contrib/auth/mixins.py", line 52, in dispatch
    return super().dispatch(request, *args, **kwargs)
  File "/usr/lib64/python3.6/site-packages/django/contrib/auth/mixins.py", line 106, in dispatch
    user_test_result = self.get_test_func()()
  File "/usr/lib64/python3.6/site-packages/django/contrib/auth/mixins.py", line 96, in test_func
    '{0} is missing the implementation of the test_func() method.'.format(self.__class__.__name__)
NotImplementedError: srDetailView is missing the implementation of the test_func() method.
[25/Mar/2019 20:09:30] "GET /serviceRequest/53097/ HTTP/1.1" 500 81591
[25/Mar/2019 20:10:43] "GET /serviceRequest/new/ HTTP/1.1" 200 6222
[25/Mar/2019 20:11:03] "GET /serviceRequest/new/ HTTP/1.1" 200 6222
Internal Server Error: /serviceRequest/new/
Traceback (most recent call last):
  File "/usr/lib64/python3.6/site-packages/django/core/handlers/exception.py", line 34, in inner
    response = get_response(request)
  File "/usr/lib64/python3.6/site-packages/django/core/handlers/base.py", line 126, in _get_response
    response = self.process_exception_by_middleware(e, request)
  File "/usr/lib64/python3.6/site-packages/django/core/handlers/base.py", line 124, in _get_response
    response = wrapped_callback(request, *callback_args, **callback_kwargs)
  File "/usr/lib64/python3.6/site-packages/django/views/generic/base.py", line 68, in view
    return self.dispatch(request, *args, **kwargs)
  File "/usr/lib64/python3.6/site-packages/django/contrib/auth/mixins.py", line 52, in dispatch
    return super().dispatch(request, *args, **kwargs)
  File "/usr/lib64/python3.6/site-packages/django/views/generic/base.py", line 88, in dispatch
    return handler(request, *args, **kwargs)
  File "/usr/lib64/python3.6/site-packages/django/views/generic/edit.py", line 172, in post
    return super().post(request, *args, **kwargs)
  File "/usr/lib64/python3.6/site-packages/django/views/generic/edit.py", line 142, in post
    return self.form_valid(form)
  File "/home/aliceyu2/CS411-CSR/teamHawkeye/serviceRequests/views.py", line 34, in form_valid
    return super().form_valid(form)
  File "/usr/lib64/python3.6/site-packages/django/views/generic/edit.py", line 125, in form_valid
    self.object = form.save()
  File "/usr/lib64/python3.6/site-packages/django/forms/models.py", line 458, in save
    self.instance.save()
  File "/home/aliceyu2/CS411-CSR/teamHawkeye/serviceRequests/models.py", line 29, in save
    oldReqNum = Request.objects.select_for_update(nowait=True).order_by('-requestNumber')[0]
  File "/usr/lib64/python3.6/site-packages/django/db/models/query.py", line 302, in __getitem__
    qs._fetch_all()
  File "/usr/lib64/python3.6/site-packages/django/db/models/query.py", line 1186, in _fetch_all
    self._result_cache = list(self._iterable_class(self))
  File "/usr/lib64/python3.6/site-packages/django/db/models/query.py", line 54, in __iter__
    results = compiler.execute_sql(chunked_fetch=self.chunked_fetch, chunk_size=self.chunk_size)
  File "/usr/lib64/python3.6/site-packages/django/db/models/sql/compiler.py", line 1052, in execute_sql
    sql, params = self.as_sql()
  File "/usr/lib64/python3.6/site-packages/django/db/models/sql/compiler.py", line 507, in as_sql
    raise NotSupportedError('NOWAIT is not supported on this database backend.')
django.db.utils.NotSupportedError: NOWAIT is not supported on this database backend.
[25/Mar/2019 20:11:05] "POST /serviceRequest/new/ HTTP/1.1" 500 132593
[25/Mar/2019 20:12:02] "GET /serviceRequest/ HTTP/1.1" 200 190835
Internal Server Error: /serviceRequest/53097/
Traceback (most recent call last):
  File "/usr/lib64/python3.6/site-packages/django/core/handlers/exception.py", line 34, in inner
    response = get_response(request)
  File "/usr/lib64/python3.6/site-packages/django/core/handlers/base.py", line 126, in _get_response
    response = self.process_exception_by_middleware(e, request)
  File "/usr/lib64/python3.6/site-packages/django/core/handlers/base.py", line 124, in _get_response
    response = wrapped_callback(request, *callback_args, **callback_kwargs)
  File "/usr/lib64/python3.6/site-packages/django/views/generic/base.py", line 68, in view
    return self.dispatch(request, *args, **kwargs)
  File "/usr/lib64/python3.6/site-packages/django/contrib/auth/mixins.py", line 52, in dispatch
    return super().dispatch(request, *args, **kwargs)
  File "/usr/lib64/python3.6/site-packages/django/contrib/auth/mixins.py", line 106, in dispatch
    user_test_result = self.get_test_func()()
  File "/usr/lib64/python3.6/site-packages/django/contrib/auth/mixins.py", line 96, in test_func
    '{0} is missing the implementation of the test_func() method.'.format(self.__class__.__name__)
NotImplementedError: srDetailView is missing the implementation of the test_func() method.
[25/Mar/2019 20:12:04] "GET /serviceRequest/53097/ HTTP/1.1" 500 81591
Internal Server Error: /serviceRequest/53098/
Traceback (most recent call last):
  File "/usr/lib64/python3.6/site-packages/django/core/handlers/exception.py", line 34, in inner
    response = get_response(request)
  File "/usr/lib64/python3.6/site-packages/django/core/handlers/base.py", line 126, in _get_response
    response = self.process_exception_by_middleware(e, request)
  File "/usr/lib64/python3.6/site-packages/django/core/handlers/base.py", line 124, in _get_response
    response = wrapped_callback(request, *callback_args, **callback_kwargs)
  File "/usr/lib64/python3.6/site-packages/django/views/generic/base.py", line 68, in view
    return self.dispatch(request, *args, **kwargs)
  File "/usr/lib64/python3.6/site-packages/django/contrib/auth/mixins.py", line 52, in dispatch
    return super().dispatch(request, *args, **kwargs)
  File "/usr/lib64/python3.6/site-packages/django/contrib/auth/mixins.py", line 106, in dispatch
    user_test_result = self.get_test_func()()
  File "/usr/lib64/python3.6/site-packages/django/contrib/auth/mixins.py", line 96, in test_func
    '{0} is missing the implementation of the test_func() method.'.format(self.__class__.__name__)
NotImplementedError: srDetailView is missing the implementation of the test_func() method.
[25/Mar/2019 20:12:09] "GET /serviceRequest/53098/ HTTP/1.1" 500 81591
[25/Mar/2019 20:12:21] "GET /serviceRequest/new/ HTTP/1.1" 200 6222
[25/Mar/2019 20:13:32] "GET / HTTP/1.1" 200 3998
Not Found: /mySearch
[25/Mar/2019 20:13:40] "GET /mySearch HTTP/1.1" 404 2882
[25/Mar/2019 20:13:43] "GET / HTTP/1.1" 200 3908
[25/Mar/2019 20:13:44] "GET /serviceRequest/ HTTP/1.1" 200 190835
Internal Server Error: /serviceRequest/53097/
Traceback (most recent call last):
  File "/usr/lib64/python3.6/site-packages/django/core/handlers/exception.py", line 34, in inner
    response = get_response(request)
  File "/usr/lib64/python3.6/site-packages/django/core/handlers/base.py", line 126, in _get_response
    response = self.process_exception_by_middleware(e, request)
  File "/usr/lib64/python3.6/site-packages/django/core/handlers/base.py", line 124, in _get_response
    response = wrapped_callback(request, *callback_args, **callback_kwargs)
  File "/usr/lib64/python3.6/site-packages/django/views/generic/base.py", line 68, in view
    return self.dispatch(request, *args, **kwargs)
  File "/usr/lib64/python3.6/site-packages/django/contrib/auth/mixins.py", line 52, in dispatch
    return super().dispatch(request, *args, **kwargs)
  File "/usr/lib64/python3.6/site-packages/django/contrib/auth/mixins.py", line 106, in dispatch
    user_test_result = self.get_test_func()()
  File "/usr/lib64/python3.6/site-packages/django/contrib/auth/mixins.py", line 96, in test_func
    '{0} is missing the implementation of the test_func() method.'.format(self.__class__.__name__)
NotImplementedError: srDetailView is missing the implementation of the test_func() method.
[25/Mar/2019 20:13:47] "GET /serviceRequest/53097/ HTTP/1.1" 500 81591
[25/Mar/2019 20:13:47] "GET /login/ HTTP/1.1" 200 3376
[25/Mar/2019 20:13:51] "POST /login/ HTTP/1.1" 302 0
[25/Mar/2019 20:13:51] "GET / HTTP/1.1" 200 3998
[25/Mar/2019 20:13:53] "GET /serviceRequest/ HTTP/1.1" 200 190835
[25/Mar/2019 20:13:54] "GET /serviceRequest/new/ HTTP/1.1" 200 6222
[25/Mar/2019 20:13:57] "GET /logout/ HTTP/1.1" 200 2299
Not Found: /mySearch
[25/Mar/2019 20:14:20] "GET /mySearch HTTP/1.1" 404 2882
[25/Mar/2019 20:14:23] "GET / HTTP/1.1" 200 3908
[25/Mar/2019 20:14:26] "GET /login/ HTTP/1.1" 200 3376
[25/Mar/2019 20:14:30] "POST /login/ HTTP/1.1" 302 0
[25/Mar/2019 20:14:30] "GET / HTTP/1.1" 200 3998
[25/Mar/2019 20:14:32] "GET /serviceRequest/ HTTP/1.1" 200 190835
Internal Server Error: /serviceRequest/53097/
Traceback (most recent call last):
  File "/usr/lib64/python3.6/site-packages/django/core/handlers/exception.py", line 34, in inner
    response = get_response(request)
  File "/usr/lib64/python3.6/site-packages/django/core/handlers/base.py", line 126, in _get_response
    response = self.process_exception_by_middleware(e, request)
  File "/usr/lib64/python3.6/site-packages/django/core/handlers/base.py", line 124, in _get_response
    response = wrapped_callback(request, *callback_args, **callback_kwargs)
  File "/usr/lib64/python3.6/site-packages/django/views/generic/base.py", line 68, in view
    return self.dispatch(request, *args, **kwargs)
  File "/usr/lib64/python3.6/site-packages/django/contrib/auth/mixins.py", line 52, in dispatch
    return super().dispatch(request, *args, **kwargs)
  File "/usr/lib64/python3.6/site-packages/django/contrib/auth/mixins.py", line 106, in dispatch
    user_test_result = self.get_test_func()()
  File "/usr/lib64/python3.6/site-packages/django/contrib/auth/mixins.py", line 96, in test_func
    '{0} is missing the implementation of the test_func() method.'.format(self.__class__.__name__)
NotImplementedError: srDetailView is missing the implementation of the test_func() method.
[25/Mar/2019 20:14:34] "GET /serviceRequest/53097/ HTTP/1.1" 500 80586
Internal Server Error: /serviceRequest/53097/
Traceback (most recent call last):
  File "/usr/lib64/python3.6/site-packages/django/core/handlers/exception.py", line 34, in inner
    response = get_response(request)
  File "/usr/lib64/python3.6/site-packages/django/core/handlers/base.py", line 126, in _get_response
    response = self.process_exception_by_middleware(e, request)
  File "/usr/lib64/python3.6/site-packages/django/core/handlers/base.py", line 124, in _get_response
    response = wrapped_callback(request, *callback_args, **callback_kwargs)
  File "/usr/lib64/python3.6/site-packages/django/views/generic/base.py", line 68, in view
    return self.dispatch(request, *args, **kwargs)
  File "/usr/lib64/python3.6/site-packages/django/contrib/auth/mixins.py", line 52, in dispatch
    return super().dispatch(request, *args, **kwargs)
  File "/usr/lib64/python3.6/site-packages/django/contrib/auth/mixins.py", line 106, in dispatch
    user_test_result = self.get_test_func()()
  File "/usr/lib64/python3.6/site-packages/django/contrib/auth/mixins.py", line 96, in test_func
    '{0} is missing the implementation of the test_func() method.'.format(self.__class__.__name__)
NotImplementedError: srDetailView is missing the implementation of the test_func() method.
[25/Mar/2019 20:14:34] "GET /serviceRequest/53097/ HTTP/1.1" 500 77447
[25/Mar/2019 20:14:45] "GET / HTTP/1.1" 200 3998
[25/Mar/2019 20:14:46] "GET /serviceRequest/ HTTP/1.1" 200 190835
[25/Mar/2019 20:14:50] "GET /profile/ HTTP/1.1" 200 6907
[25/Mar/2019 20:14:50] "GET /media/default.jpg HTTP/1.1" 200 7199
[25/Mar/2019 20:14:57] "GET /serviceRequest/new/ HTTP/1.1" 200 6222
[25/Mar/2019 20:15:01] "GET / HTTP/1.1" 200 3998
[25/Mar/2019 20:15:02] "GET /serviceRequest/ HTTP/1.1" 200 190835
Internal Server Error: /serviceRequest/new/
Traceback (most recent call last):
  File "/usr/lib64/python3.6/site-packages/django/core/handlers/exception.py", line 34, in inner
    response = get_response(request)
  File "/usr/lib64/python3.6/site-packages/django/core/handlers/base.py", line 126, in _get_response
    response = self.process_exception_by_middleware(e, request)
  File "/usr/lib64/python3.6/site-packages/django/core/handlers/base.py", line 124, in _get_response
    response = wrapped_callback(request, *callback_args, **callback_kwargs)
  File "/usr/lib64/python3.6/site-packages/django/views/generic/base.py", line 68, in view
    return self.dispatch(request, *args, **kwargs)
  File "/usr/lib64/python3.6/site-packages/django/contrib/auth/mixins.py", line 52, in dispatch
    return super().dispatch(request, *args, **kwargs)
  File "/usr/lib64/python3.6/site-packages/django/views/generic/base.py", line 88, in dispatch
    return handler(request, *args, **kwargs)
  File "/usr/lib64/python3.6/site-packages/django/views/generic/edit.py", line 172, in post
    return super().post(request, *args, **kwargs)
  File "/usr/lib64/python3.6/site-packages/django/views/generic/edit.py", line 142, in post
    return self.form_valid(form)
  File "/home/aliceyu2/CS411-CSR/teamHawkeye/serviceRequests/views.py", line 34, in form_valid
    return super().form_valid(form)
  File "/usr/lib64/python3.6/site-packages/django/views/generic/edit.py", line 125, in form_valid
    self.object = form.save()
  File "/usr/lib64/python3.6/site-packages/django/forms/models.py", line 458, in save
    self.instance.save()
  File "/home/aliceyu2/CS411-CSR/teamHawkeye/serviceRequests/models.py", line 29, in save
    oldReqNum = Request.objects.select_for_update(nowait=True).order_by('-requestNumber')[0]
  File "/usr/lib64/python3.6/site-packages/django/db/models/query.py", line 302, in __getitem__
    qs._fetch_all()
  File "/usr/lib64/python3.6/site-packages/django/db/models/query.py", line 1186, in _fetch_all
    self._result_cache = list(self._iterable_class(self))
  File "/usr/lib64/python3.6/site-packages/django/db/models/query.py", line 54, in __iter__
    results = compiler.execute_sql(chunked_fetch=self.chunked_fetch, chunk_size=self.chunk_size)
  File "/usr/lib64/python3.6/site-packages/django/db/models/sql/compiler.py", line 1052, in execute_sql
    sql, params = self.as_sql()
  File "/usr/lib64/python3.6/site-packages/django/db/models/sql/compiler.py", line 507, in as_sql
    raise NotSupportedError('NOWAIT is not supported on this database backend.')
django.db.utils.NotSupportedError: NOWAIT is not supported on this database backend.
[25/Mar/2019 20:15:14] "POST /serviceRequest/new/ HTTP/1.1" 500 128453
[25/Mar/2019 20:15:50] "GET / HTTP/1.1" 200 3998
[25/Mar/2019 20:15:51] "GET /serviceRequest/ HTTP/1.1" 200 190835
[25/Mar/2019 20:15:53] "GET /profile/ HTTP/1.1" 200 6907
[25/Mar/2019 20:15:55] "GET /logout/ HTTP/1.1" 200 2299
[25/Mar/2019 20:15:57] "GET /login/ HTTP/1.1" 200 3376
[25/Mar/2019 20:15:58] "POST /login/ HTTP/1.1" 302 0
[25/Mar/2019 20:15:58] "GET / HTTP/1.1" 200 3998
[25/Mar/2019 20:16:00] "GET /serviceRequest/ HTTP/1.1" 200 190835
Internal Server Error: /serviceRequest/53097/
Traceback (most recent call last):
  File "/usr/lib64/python3.6/site-packages/django/core/handlers/exception.py", line 34, in inner
    response = get_response(request)
  File "/usr/lib64/python3.6/site-packages/django/core/handlers/base.py", line 126, in _get_response
    response = self.process_exception_by_middleware(e, request)
  File "/usr/lib64/python3.6/site-packages/django/core/handlers/base.py", line 124, in _get_response
    response = wrapped_callback(request, *callback_args, **callback_kwargs)
  File "/usr/lib64/python3.6/site-packages/django/views/generic/base.py", line 68, in view
    return self.dispatch(request, *args, **kwargs)
  File "/usr/lib64/python3.6/site-packages/django/contrib/auth/mixins.py", line 52, in dispatch
    return super().dispatch(request, *args, **kwargs)
  File "/usr/lib64/python3.6/site-packages/django/contrib/auth/mixins.py", line 106, in dispatch
    user_test_result = self.get_test_func()()
  File "/usr/lib64/python3.6/site-packages/django/contrib/auth/mixins.py", line 96, in test_func
    '{0} is missing the implementation of the test_func() method.'.format(self.__class__.__name__)
NotImplementedError: srDetailView is missing the implementation of the test_func() method.
[25/Mar/2019 20:16:02] "GET /serviceRequest/53097/ HTTP/1.1" 500 81591
Internal Server Error: /serviceRequest/53097/
Traceback (most recent call last):
  File "/usr/lib64/python3.6/site-packages/django/core/handlers/exception.py", line 34, in inner
    response = get_response(request)
  File "/usr/lib64/python3.6/site-packages/django/core/handlers/base.py", line 126, in _get_response
    response = self.process_exception_by_middleware(e, request)
  File "/usr/lib64/python3.6/site-packages/django/core/handlers/base.py", line 124, in _get_response
    response = wrapped_callback(request, *callback_args, **callback_kwargs)
  File "/usr/lib64/python3.6/site-packages/django/views/generic/base.py", line 68, in view
    return self.dispatch(request, *args, **kwargs)
  File "/usr/lib64/python3.6/site-packages/django/contrib/auth/mixins.py", line 52, in dispatch
    return super().dispatch(request, *args, **kwargs)
  File "/usr/lib64/python3.6/site-packages/django/contrib/auth/mixins.py", line 106, in dispatch
    user_test_result = self.get_test_func()()
  File "/usr/lib64/python3.6/site-packages/django/contrib/auth/mixins.py", line 96, in test_func
    '{0} is missing the implementation of the test_func() method.'.format(self.__class__.__name__)
NotImplementedError: srDetailView is missing the implementation of the test_func() method.
[25/Mar/2019 20:20:27] "GET /serviceRequest/53097/ HTTP/1.1" 500 81591
[25/Mar/2019 20:22:20] "GET /serviceRequest/ HTTP/1.1" 200 190835
[25/Mar/2019 20:24:54] "GET /serviceRequest/ HTTP/1.1" 200 190835
[25/Mar/2019 20:24:55] "GET /serviceRequest/53097/ HTTP/1.1" 200 2878
[25/Mar/2019 20:25:11] "GET /serviceRequest/ HTTP/1.1" 200 190835
[25/Mar/2019 20:25:12] "GET /serviceRequest/new/ HTTP/1.1" 200 6222
Internal Server Error: /serviceRequest/new/
Traceback (most recent call last):
  File "/usr/lib64/python3.6/site-packages/django/core/handlers/exception.py", line 34, in inner
    response = get_response(request)
  File "/usr/lib64/python3.6/site-packages/django/core/handlers/base.py", line 126, in _get_response
    response = self.process_exception_by_middleware(e, request)
  File "/usr/lib64/python3.6/site-packages/django/core/handlers/base.py", line 124, in _get_response
    response = wrapped_callback(request, *callback_args, **callback_kwargs)
  File "/usr/lib64/python3.6/site-packages/django/views/generic/base.py", line 68, in view
    return self.dispatch(request, *args, **kwargs)
  File "/usr/lib64/python3.6/site-packages/django/contrib/auth/mixins.py", line 52, in dispatch
    return super().dispatch(request, *args, **kwargs)
  File "/usr/lib64/python3.6/site-packages/django/views/generic/base.py", line 88, in dispatch
    return handler(request, *args, **kwargs)
  File "/usr/lib64/python3.6/site-packages/django/views/generic/edit.py", line 172, in post
    return super().post(request, *args, **kwargs)
  File "/usr/lib64/python3.6/site-packages/django/views/generic/edit.py", line 142, in post
    return self.form_valid(form)
  File "/home/aliceyu2/CS411-CSR/teamHawkeye/serviceRequests/views.py", line 40, in form_valid
    return super().form_valid(form)
  File "/usr/lib64/python3.6/site-packages/django/views/generic/edit.py", line 125, in form_valid
    self.object = form.save()
  File "/usr/lib64/python3.6/site-packages/django/forms/models.py", line 458, in save
    self.instance.save()
  File "/home/aliceyu2/CS411-CSR/teamHawkeye/serviceRequests/models.py", line 29, in save
    oldReqNum = Request.objects.select_for_update(nowait=True).order_by('-requestNumber')[0]
  File "/usr/lib64/python3.6/site-packages/django/db/models/query.py", line 302, in __getitem__
    qs._fetch_all()
  File "/usr/lib64/python3.6/site-packages/django/db/models/query.py", line 1186, in _fetch_all
    self._result_cache = list(self._iterable_class(self))
  File "/usr/lib64/python3.6/site-packages/django/db/models/query.py", line 54, in __iter__
    results = compiler.execute_sql(chunked_fetch=self.chunked_fetch, chunk_size=self.chunk_size)
  File "/usr/lib64/python3.6/site-packages/django/db/models/sql/compiler.py", line 1052, in execute_sql
    sql, params = self.as_sql()
  File "/usr/lib64/python3.6/site-packages/django/db/models/sql/compiler.py", line 507, in as_sql
    raise NotSupportedError('NOWAIT is not supported on this database backend.')
django.db.utils.NotSupportedError: NOWAIT is not supported on this database backend.
[25/Mar/2019 20:25:39] "POST /serviceRequest/new/ HTTP/1.1" 500 128455
Performing system checks...

System check identified no issues (0 silenced).
March 25, 2019 - 20:24:43
Django version 2.1.7, using settings 'teamHawkeye.settings'
Starting development server at http://sp19-cs411-12.cs.illinois.edu:8000/
Quit the server with CONTROL-C.
Internal Server Error: /serviceRequest/new/
Traceback (most recent call last):
  File "/usr/lib64/python3.6/site-packages/django/core/handlers/exception.py", line 34, in inner
    response = get_response(request)
  File "/usr/lib64/python3.6/site-packages/django/core/handlers/base.py", line 126, in _get_response
    response = self.process_exception_by_middleware(e, request)
  File "/usr/lib64/python3.6/site-packages/django/core/handlers/base.py", line 124, in _get_response
    response = wrapped_callback(request, *callback_args, **callback_kwargs)
  File "/usr/lib64/python3.6/site-packages/django/views/generic/base.py", line 68, in view
    return self.dispatch(request, *args, **kwargs)
  File "/usr/lib64/python3.6/site-packages/django/contrib/auth/mixins.py", line 52, in dispatch
    return super().dispatch(request, *args, **kwargs)
  File "/usr/lib64/python3.6/site-packages/django/views/generic/base.py", line 88, in dispatch
    return handler(request, *args, **kwargs)
  File "/usr/lib64/python3.6/site-packages/django/views/generic/edit.py", line 172, in post
    return super().post(request, *args, **kwargs)
  File "/usr/lib64/python3.6/site-packages/django/views/generic/edit.py", line 142, in post
    return self.form_valid(form)
  File "/home/aliceyu2/CS411-CSR/teamHawkeye/serviceRequests/views.py", line 40, in form_valid
    return super().form_valid(form)
  File "/usr/lib64/python3.6/site-packages/django/views/generic/edit.py", line 125, in form_valid
    self.object = form.save()
  File "/usr/lib64/python3.6/site-packages/django/forms/models.py", line 458, in save
    self.instance.save()
  File "/home/aliceyu2/CS411-CSR/teamHawkeye/serviceRequests/models.py", line 29, in save
    oldReqNum = Request.objects.select_for_update(nowait=True).order_by('-requestNumber')[0]
  File "/usr/lib64/python3.6/site-packages/django/db/models/query.py", line 302, in __getitem__
    qs._fetch_all()
  File "/usr/lib64/python3.6/site-packages/django/db/models/query.py", line 1186, in _fetch_all
    self._result_cache = list(self._iterable_class(self))
  File "/usr/lib64/python3.6/site-packages/django/db/models/query.py", line 54, in __iter__
    results = compiler.execute_sql(chunked_fetch=self.chunked_fetch, chunk_size=self.chunk_size)
  File "/usr/lib64/python3.6/site-packages/django/db/models/sql/compiler.py", line 1052, in execute_sql
    sql, params = self.as_sql()
  File "/usr/lib64/python3.6/site-packages/django/db/models/sql/compiler.py", line 507, in as_sql
    raise NotSupportedError('NOWAIT is not supported on this database backend.')
django.db.utils.NotSupportedError: NOWAIT is not supported on this database backend.
[25/Mar/2019 20:31:54] "POST /serviceRequest/new/ HTTP/1.1" 500 128455
Performing system checks...

System check identified no issues (0 silenced).
March 25, 2019 - 20:31:07
Django version 2.1.7, using settings 'teamHawkeye.settings'
Starting development server at http://sp19-cs411-12.cs.illinois.edu:8000/
Quit the server with CONTROL-C.
Performing system checks...

System check identified no issues (0 silenced).
March 25, 2019 - 20:34:15
Django version 2.1.7, using settings 'teamHawkeye.settings'
Starting development server at http://sp19-cs411-12.cs.illinois.edu:8000/
Quit the server with CONTROL-C.
[25/Mar/2019 20:35:38] "POST /serviceRequest/new/ HTTP/1.1" 302 0
[25/Mar/2019 20:35:38] "GET /serviceRequest/60375/ HTTP/1.1" 200 2880
[25/Mar/2019 20:35:49] "GET /serviceRequest/ HTTP/1.1" 200 190836
[25/Mar/2019 20:35:52] "GET /serviceRequest/new/ HTTP/1.1" 200 6222
[25/Mar/2019 20:35:57] "POST /serviceRequest/new/ HTTP/1.1" 302 0
[25/Mar/2019 20:35:57] "GET /serviceRequest/60376/ HTTP/1.1" 200 2874
[25/Mar/2019 20:35:58] "GET /serviceRequest/ HTTP/1.1" 200 190831
[25/Mar/2019 20:36:03] "GET /serviceRequest/60375/ HTTP/1.1" 200 2880
[25/Mar/2019 20:36:05] "GET /serviceRequest/60375/update/ HTTP/1.1" 200 6237
[25/Mar/2019 20:36:11] "POST /serviceRequest/60375/update/ HTTP/1.1" 302 0
[25/Mar/2019 20:36:11] "GET /serviceRequest/60375/ HTTP/1.1" 200 2883
[25/Mar/2019 20:36:12] "GET /serviceRequest/ HTTP/1.1" 200 190834
[25/Mar/2019 20:36:18] "GET /serviceRequest/60375/ HTTP/1.1" 200 2883
[25/Mar/2019 20:36:20] "GET /serviceRequest/60375/delete/ HTTP/1.1" 200 2820
[25/Mar/2019 20:36:22] "GET /serviceRequest/60375/ HTTP/1.1" 200 2883
[25/Mar/2019 20:36:24] "GET /serviceRequest/60375/delete/ HTTP/1.1" 200 2820
[25/Mar/2019 20:36:25] "POST /serviceRequest/60375/delete/ HTTP/1.1" 302 0
[25/Mar/2019 20:36:26] "GET /serviceRequest/ HTTP/1.1" 200 190830
[25/Mar/2019 20:36:27] "GET /serviceRequest/new/ HTTP/1.1" 200 6222
[25/Mar/2019 20:36:38] "POST /serviceRequest/new/ HTTP/1.1" 302 0
[25/Mar/2019 20:36:38] "GET /serviceRequest/60377/ HTTP/1.1" 200 2883
[25/Mar/2019 20:36:40] "GET /serviceRequest/ HTTP/1.1" 200 190834
[25/Mar/2019 20:58:53] "GET / HTTP/1.1" 200 3998
Not Found: /favicon.ico
[25/Mar/2019 20:58:54] "GET /favicon.ico HTTP/1.1" 404 2891
[25/Mar/2019 20:58:57] "GET /serviceRequest/ HTTP/1.1" 200 190834
[25/Mar/2019 20:58:59] "GET / HTTP/1.1" 200 3998
[25/Mar/2019 20:59:01] "GET /serviceRequest/ HTTP/1.1" 200 190834
Forbidden (Permission denied): /serviceRequest/60377/
Traceback (most recent call last):
  File "/usr/lib64/python3.6/site-packages/django/core/handlers/exception.py", line 34, in inner
    response = get_response(request)
  File "/usr/lib64/python3.6/site-packages/django/core/handlers/base.py", line 126, in _get_response
    response = self.process_exception_by_middleware(e, request)
  File "/usr/lib64/python3.6/site-packages/django/core/handlers/base.py", line 124, in _get_response
    response = wrapped_callback(request, *callback_args, **callback_kwargs)
  File "/usr/lib64/python3.6/site-packages/django/views/generic/base.py", line 68, in view
    return self.dispatch(request, *args, **kwargs)
  File "/usr/lib64/python3.6/site-packages/django/contrib/auth/mixins.py", line 52, in dispatch
    return super().dispatch(request, *args, **kwargs)
  File "/usr/lib64/python3.6/site-packages/django/contrib/auth/mixins.py", line 108, in dispatch
    return self.handle_no_permission()
  File "/usr/lib64/python3.6/site-packages/django/contrib/auth/mixins.py", line 43, in handle_no_permission
    raise PermissionDenied(self.get_permission_denied_message())
django.core.exceptions.PermissionDenied
[25/Mar/2019 20:59:05] "GET /serviceRequest/60377/ HTTP/1.1" 403 22
[25/Mar/2019 20:59:09] "GET /serviceRequest/ HTTP/1.1" 200 190834
[25/Mar/2019 20:59:11] "GET /serviceRequest/ HTTP/1.1" 200 190834
[25/Mar/2019 20:59:12] "GET / HTTP/1.1" 200 3998
[25/Mar/2019 20:59:13] "GET / HTTP/1.1" 200 3998
[25/Mar/2019 20:59:14] "GET /serviceRequest/ HTTP/1.1" 200 190834
[25/Mar/2019 20:59:15] "GET / HTTP/1.1" 200 3998
[25/Mar/2019 20:59:18] "GET /serviceRequest/ HTTP/1.1" 200 190834
[25/Mar/2019 20:59:19] "GET /profile/ HTTP/1.1" 200 6907
[25/Mar/2019 20:59:22] "GET /serviceRequest/ HTTP/1.1" 200 190834
[25/Mar/2019 20:59:25] "GET /serviceRequest/new/ HTTP/1.1" 200 6222
[25/Mar/2019 20:59:26] "POST /serviceRequest/new/ HTTP/1.1" 302 0
[25/Mar/2019 20:59:27] "GET /serviceRequest/60378/ HTTP/1.1" 200 2874
[25/Mar/2019 20:59:29] "GET / HTTP/1.1" 200 3998
[25/Mar/2019 20:59:31] "GET /serviceRequest/ HTTP/1.1" 200 190828
[25/Mar/2019 20:59:34] "GET /serviceRequest/60378/ HTTP/1.1" 200 2874
[25/Mar/2019 20:59:37] "GET /serviceRequest/ HTTP/1.1" 200 190828
[25/Mar/2019 20:59:37] "GET / HTTP/1.1" 200 3998
[25/Mar/2019 20:59:39] "GET /serviceRequest/ HTTP/1.1" 200 190828
Forbidden (Permission denied): /serviceRequest/60377/
Traceback (most recent call last):
  File "/usr/lib64/python3.6/site-packages/django/core/handlers/exception.py", line 34, in inner
    response = get_response(request)
  File "/usr/lib64/python3.6/site-packages/django/core/handlers/base.py", line 126, in _get_response
    response = self.process_exception_by_middleware(e, request)
  File "/usr/lib64/python3.6/site-packages/django/core/handlers/base.py", line 124, in _get_response
    response = wrapped_callback(request, *callback_args, **callback_kwargs)
  File "/usr/lib64/python3.6/site-packages/django/views/generic/base.py", line 68, in view
    return self.dispatch(request, *args, **kwargs)
  File "/usr/lib64/python3.6/site-packages/django/contrib/auth/mixins.py", line 52, in dispatch
    return super().dispatch(request, *args, **kwargs)
  File "/usr/lib64/python3.6/site-packages/django/contrib/auth/mixins.py", line 108, in dispatch
    return self.handle_no_permission()
  File "/usr/lib64/python3.6/site-packages/django/contrib/auth/mixins.py", line 43, in handle_no_permission
    raise PermissionDenied(self.get_permission_denied_message())
django.core.exceptions.PermissionDenied
[25/Mar/2019 20:59:42] "GET /serviceRequest/60377/ HTTP/1.1" 403 22
[25/Mar/2019 20:59:46] "GET /serviceRequest/60378/ HTTP/1.1" 200 2874
[25/Mar/2019 20:59:50] "GET /serviceRequest/ HTTP/1.1" 200 190828
Forbidden (Permission denied): /serviceRequest/60376/
Traceback (most recent call last):
  File "/usr/lib64/python3.6/site-packages/django/core/handlers/exception.py", line 34, in inner
    response = get_response(request)
  File "/usr/lib64/python3.6/site-packages/django/core/handlers/base.py", line 126, in _get_response
    response = self.process_exception_by_middleware(e, request)
  File "/usr/lib64/python3.6/site-packages/django/core/handlers/base.py", line 124, in _get_response
    response = wrapped_callback(request, *callback_args, **callback_kwargs)
  File "/usr/lib64/python3.6/site-packages/django/views/generic/base.py", line 68, in view
    return self.dispatch(request, *args, **kwargs)
  File "/usr/lib64/python3.6/site-packages/django/contrib/auth/mixins.py", line 52, in dispatch
    return super().dispatch(request, *args, **kwargs)
  File "/usr/lib64/python3.6/site-packages/django/contrib/auth/mixins.py", line 108, in dispatch
    return self.handle_no_permission()
  File "/usr/lib64/python3.6/site-packages/django/contrib/auth/mixins.py", line 43, in handle_no_permission
    raise PermissionDenied(self.get_permission_denied_message())
django.core.exceptions.PermissionDenied
[25/Mar/2019 20:59:51] "GET /serviceRequest/60376/ HTTP/1.1" 403 22
Forbidden (Permission denied): /serviceRequest/53097/
Traceback (most recent call last):
  File "/usr/lib64/python3.6/site-packages/django/core/handlers/exception.py", line 34, in inner
    response = get_response(request)
  File "/usr/lib64/python3.6/site-packages/django/core/handlers/base.py", line 126, in _get_response
    response = self.process_exception_by_middleware(e, request)
  File "/usr/lib64/python3.6/site-packages/django/core/handlers/base.py", line 124, in _get_response
    response = wrapped_callback(request, *callback_args, **callback_kwargs)
  File "/usr/lib64/python3.6/site-packages/django/views/generic/base.py", line 68, in view
    return self.dispatch(request, *args, **kwargs)
  File "/usr/lib64/python3.6/site-packages/django/contrib/auth/mixins.py", line 52, in dispatch
    return super().dispatch(request, *args, **kwargs)
  File "/usr/lib64/python3.6/site-packages/django/contrib/auth/mixins.py", line 108, in dispatch
    return self.handle_no_permission()
  File "/usr/lib64/python3.6/site-packages/django/contrib/auth/mixins.py", line 43, in handle_no_permission
    raise PermissionDenied(self.get_permission_denied_message())
django.core.exceptions.PermissionDenied
[25/Mar/2019 20:59:57] "GET /serviceRequest/53097/ HTTP/1.1" 403 22
[25/Mar/2019 21:00:06] "GET /serviceRequest/new/ HTTP/1.1" 200 6222
[25/Mar/2019 21:00:07] "POST /serviceRequest/new/ HTTP/1.1" 302 0
[25/Mar/2019 21:00:07] "GET /serviceRequest/60379/ HTTP/1.1" 200 2874
[25/Mar/2019 21:00:10] "GET /serviceRequest/ HTTP/1.1" 200 190827
[25/Mar/2019 21:00:13] "GET /serviceRequest/60379/ HTTP/1.1" 200 2874
[25/Mar/2019 21:00:18] "GET /serviceRequest/ HTTP/1.1" 200 190827
[25/Mar/2019 21:00:20] "GET /logout/ HTTP/1.1" 200 2299
[25/Mar/2019 21:00:22] "GET /login/ HTTP/1.1" 200 3376
[25/Mar/2019 21:00:23] "GET / HTTP/1.1" 200 3908
[25/Mar/2019 21:00:28] "GET /serviceRequest/ HTTP/1.1" 302 0
[25/Mar/2019 21:00:28] "GET /login/?next=/serviceRequest/ HTTP/1.1" 200 3376
[25/Mar/2019 21:00:32] "POST /login/?next=/serviceRequest/ HTTP/1.1" 302 0
[25/Mar/2019 21:00:32] "GET /serviceRequest/ HTTP/1.1" 200 190827
Forbidden (Permission denied): /serviceRequest/60377/
Traceback (most recent call last):
  File "/usr/lib64/python3.6/site-packages/django/core/handlers/exception.py", line 34, in inner
    response = get_response(request)
  File "/usr/lib64/python3.6/site-packages/django/core/handlers/base.py", line 126, in _get_response
    response = self.process_exception_by_middleware(e, request)
  File "/usr/lib64/python3.6/site-packages/django/core/handlers/base.py", line 124, in _get_response
    response = wrapped_callback(request, *callback_args, **callback_kwargs)
  File "/usr/lib64/python3.6/site-packages/django/views/generic/base.py", line 68, in view
    return self.dispatch(request, *args, **kwargs)
  File "/usr/lib64/python3.6/site-packages/django/contrib/auth/mixins.py", line 52, in dispatch
    return super().dispatch(request, *args, **kwargs)
  File "/usr/lib64/python3.6/site-packages/django/contrib/auth/mixins.py", line 108, in dispatch
    return self.handle_no_permission()
  File "/usr/lib64/python3.6/site-packages/django/contrib/auth/mixins.py", line 43, in handle_no_permission
    raise PermissionDenied(self.get_permission_denied_message())
django.core.exceptions.PermissionDenied
[25/Mar/2019 21:00:36] "GET /serviceRequest/60377/ HTTP/1.1" 403 22
[29/Mar/2019 19:30:17] "GET /serviceRequest/ HTTP/1.1" 200 190827
[29/Mar/2019 19:30:17] "GET /static/home/main.css HTTP/1.1" 304 0
Not Found: /favicon.ico
[29/Mar/2019 19:30:18] "GET /favicon.ico HTTP/1.1" 404 2891
[29/Mar/2019 19:30:26] "GET /logout/ HTTP/1.1" 200 2299
[29/Mar/2019 19:30:30] "GET /serviceRequest/ HTTP/1.1" 302 0
[29/Mar/2019 19:30:30] "GET /login/?next=/serviceRequest/ HTTP/1.1" 200 3376
[29/Mar/2019 19:30:45] "POST /login/?next=/serviceRequest/ HTTP/1.1" 302 0
[29/Mar/2019 19:30:46] "GET /serviceRequest/ HTTP/1.1" 200 190827
[29/Mar/2019 19:30:50] "GET /serviceRequest/60379/ HTTP/1.1" 200 2874
[29/Mar/2019 19:30:55] "GET /serviceRequest/60378/ HTTP/1.1" 200 2874
Forbidden (Permission denied): /serviceRequest/60377/
Traceback (most recent call last):
  File "/usr/lib64/python3.6/site-packages/django/core/handlers/exception.py", line 34, in inner
    response = get_response(request)
  File "/usr/lib64/python3.6/site-packages/django/core/handlers/base.py", line 126, in _get_response
    response = self.process_exception_by_middleware(e, request)
  File "/usr/lib64/python3.6/site-packages/django/core/handlers/base.py", line 124, in _get_response
    response = wrapped_callback(request, *callback_args, **callback_kwargs)
  File "/usr/lib64/python3.6/site-packages/django/views/generic/base.py", line 68, in view
    return self.dispatch(request, *args, **kwargs)
  File "/usr/lib64/python3.6/site-packages/django/contrib/auth/mixins.py", line 52, in dispatch
    return super().dispatch(request, *args, **kwargs)
  File "/usr/lib64/python3.6/site-packages/django/contrib/auth/mixins.py", line 108, in dispatch
    return self.handle_no_permission()
  File "/usr/lib64/python3.6/site-packages/django/contrib/auth/mixins.py", line 43, in handle_no_permission
    raise PermissionDenied(self.get_permission_denied_message())
django.core.exceptions.PermissionDenied
[29/Mar/2019 19:31:00] "GET /serviceRequest/60377/ HTTP/1.1" 403 22
[29/Mar/2019 19:31:05] "GET / HTTP/1.1" 200 3998
[29/Mar/2019 19:31:05] "GET /media/chicago_skyline.jpg HTTP/1.1" 304 0
[29/Mar/2019 19:31:08] "GET /serviceRequest/ HTTP/1.1" 200 190827
[29/Mar/2019 19:31:11] "GET /profile/ HTTP/1.1" 200 6907
[29/Mar/2019 19:31:11] "GET /media/default.jpg HTTP/1.1" 304 0
[29/Mar/2019 19:31:14] "GET /logout/ HTTP/1.1" 200 2299
[29/Mar/2019 19:31:17] "GET / HTTP/1.1" 200 3908
[29/Mar/2019 19:46:44] "GET / HTTP/1.1" 200 3908
[29/Mar/2019 19:46:49] "GET / HTTP/1.1" 200 3908
[29/Mar/2019 19:56:31] "GET /login/ HTTP/1.1" 200 3376
[29/Mar/2019 19:56:32] "GET /register/ HTTP/1.1" 200 4609
[29/Mar/2019 19:57:17] "POST /register/ HTTP/1.1" 200 5271
[29/Mar/2019 19:58:22] "POST /register/ HTTP/1.1" 200 5021
[29/Mar/2019 19:58:52] "POST /register/ HTTP/1.1" 302 0
[29/Mar/2019 19:58:52] "GET /login/ HTTP/1.1" 200 3376
[29/Mar/2019 20:02:43] "GET /login/ HTTP/1.1" 200 3376
[29/Mar/2019 20:02:49] "GET / HTTP/1.1" 200 3908
[29/Mar/2019 20:02:52] "GET / HTTP/1.1" 200 3908
[29/Mar/2019 20:02:53] "GET / HTTP/1.1" 200 3908
[29/Mar/2019 20:03:01] "GET /login/ HTTP/1.1" 200 3376
[29/Mar/2019 20:03:06] "GET /register/ HTTP/1.1" 200 4609
[29/Mar/2019 20:03:08] "GET /login/ HTTP/1.1" 200 3376
[29/Mar/2019 20:03:18] "POST /login/ HTTP/1.1" 200 3553
[29/Mar/2019 20:03:22] "GET /register/ HTTP/1.1" 200 4609
[29/Mar/2019 20:04:08] "POST /register/ HTTP/1.1" 200 5271
[29/Mar/2019 20:13:40] "GET / HTTP/1.1" 200 3908
Not Found: /favicon.ico
[29/Mar/2019 20:13:41] "GET /favicon.ico HTTP/1.1" 404 2891
[29/Mar/2019 20:13:52] "GET / HTTP/1.1" 200 3908
[29/Mar/2019 20:14:00] "GET /register/ HTTP/1.1" 200 4609
[29/Mar/2019 20:14:02] "GET /login/ HTTP/1.1" 200 3376
[29/Mar/2019 20:14:11] "POST /login/ HTTP/1.1" 200 3553
[29/Mar/2019 20:14:15] "GET /register/ HTTP/1.1" 200 4609
[29/Mar/2019 20:14:20] "GET /register/ HTTP/1.1" 200 4609
[29/Mar/2019 20:15:02] "POST /register/ HTTP/1.1" 200 5271
[29/Mar/2019 20:57:58] "GET / HTTP/1.1" 200 3908
Not Found: /favicon.ico
[29/Mar/2019 20:57:59] "GET /favicon.ico HTTP/1.1" 404 2891
[29/Mar/2019 20:58:01] "GET / HTTP/1.1" 200 3908
[29/Mar/2019 20:58:04] "GET /login/ HTTP/1.1" 200 3376
[29/Mar/2019 20:58:05] "GET /register/ HTTP/1.1" 200 4609
[29/Mar/2019 20:58:07] "GET / HTTP/1.1" 200 3908
[29/Mar/2019 20:58:08] "GET / HTTP/1.1" 200 3908
[29/Mar/2019 20:58:14] "GET /login/ HTTP/1.1" 200 3376
[29/Mar/2019 20:58:19] "POST /login/ HTTP/1.1" 200 3551
[29/Mar/2019 20:58:21] "GET /register/ HTTP/1.1" 200 4609
[29/Mar/2019 20:58:54] "POST /register/ HTTP/1.1" 200 5271
[29/Mar/2019 20:59:18] "POST /register/ HTTP/1.1" 200 4782
[29/Mar/2019 20:59:40] "POST /register/ HTTP/1.1" 200 4782
[29/Mar/2019 21:00:01] "POST /register/ HTTP/1.1" 302 0
[29/Mar/2019 21:00:01] "GET /login/ HTTP/1.1" 200 3376
[29/Mar/2019 21:00:13] "POST /login/ HTTP/1.1" 302 0
[29/Mar/2019 21:00:13] "GET / HTTP/1.1" 200 3998
[29/Mar/2019 21:00:31] "GET /serviceRequest/ HTTP/1.1" 200 190827
Forbidden (Permission denied): /serviceRequest/60379/
Traceback (most recent call last):
  File "/usr/lib64/python3.6/site-packages/django/core/handlers/exception.py", line 34, in inner
    response = get_response(request)
  File "/usr/lib64/python3.6/site-packages/django/core/handlers/base.py", line 126, in _get_response
    response = self.process_exception_by_middleware(e, request)
  File "/usr/lib64/python3.6/site-packages/django/core/handlers/base.py", line 124, in _get_response
    response = wrapped_callback(request, *callback_args, **callback_kwargs)
  File "/usr/lib64/python3.6/site-packages/django/views/generic/base.py", line 68, in view
    return self.dispatch(request, *args, **kwargs)
  File "/usr/lib64/python3.6/site-packages/django/contrib/auth/mixins.py", line 52, in dispatch
    return super().dispatch(request, *args, **kwargs)
  File "/usr/lib64/python3.6/site-packages/django/contrib/auth/mixins.py", line 108, in dispatch
    return self.handle_no_permission()
  File "/usr/lib64/python3.6/site-packages/django/contrib/auth/mixins.py", line 43, in handle_no_permission
    raise PermissionDenied(self.get_permission_denied_message())
django.core.exceptions.PermissionDenied
[29/Mar/2019 21:03:36] "GET /serviceRequest/60379/ HTTP/1.1" 403 22
Forbidden (Permission denied): /serviceRequest/60379/
Traceback (most recent call last):
  File "/usr/lib64/python3.6/site-packages/django/core/handlers/exception.py", line 34, in inner
    response = get_response(request)
  File "/usr/lib64/python3.6/site-packages/django/core/handlers/base.py", line 126, in _get_response
    response = self.process_exception_by_middleware(e, request)
  File "/usr/lib64/python3.6/site-packages/django/core/handlers/base.py", line 124, in _get_response
    response = wrapped_callback(request, *callback_args, **callback_kwargs)
  File "/usr/lib64/python3.6/site-packages/django/views/generic/base.py", line 68, in view
    return self.dispatch(request, *args, **kwargs)
  File "/usr/lib64/python3.6/site-packages/django/contrib/auth/mixins.py", line 52, in dispatch
    return super().dispatch(request, *args, **kwargs)
  File "/usr/lib64/python3.6/site-packages/django/contrib/auth/mixins.py", line 108, in dispatch
    return self.handle_no_permission()
  File "/usr/lib64/python3.6/site-packages/django/contrib/auth/mixins.py", line 43, in handle_no_permission
    raise PermissionDenied(self.get_permission_denied_message())
django.core.exceptions.PermissionDenied
[29/Mar/2019 21:03:52] "GET /serviceRequest/60379/ HTTP/1.1" 403 22
[29/Mar/2019 21:04:07] "GET /serviceRequest/new/ HTTP/1.1" 200 6222
[29/Mar/2019 21:04:35] "POST /serviceRequest/new/ HTTP/1.1" 302 0
[29/Mar/2019 21:04:35] "GET /serviceRequest/60380/ HTTP/1.1" 200 2877
[29/Mar/2019 21:04:51] "GET /serviceRequest/60380/update/ HTTP/1.1" 200 6231
[29/Mar/2019 21:05:05] "POST /serviceRequest/60380/update/ HTTP/1.1" 302 0
[29/Mar/2019 21:05:06] "GET /serviceRequest/60380/ HTTP/1.1" 200 2877
[29/Mar/2019 21:05:20] "GET /serviceRequest/ HTTP/1.1" 200 190825
[29/Mar/2019 21:05:26] "GET /serviceRequest/60380/ HTTP/1.1" 200 2877
[29/Mar/2019 21:05:31] "GET /serviceRequest/ HTTP/1.1" 200 190825
[29/Mar/2019 21:05:33] "GET /serviceRequest/new/ HTTP/1.1" 200 6222
[29/Mar/2019 21:05:43] "POST /serviceRequest/new/ HTTP/1.1" 302 0
[29/Mar/2019 21:05:43] "GET /serviceRequest/60381/ HTTP/1.1" 200 2877
[29/Mar/2019 21:05:45] "GET /serviceRequest/ HTTP/1.1" 200 190820
[29/Mar/2019 21:06:03] "GET /serviceRequest/60381/ HTTP/1.1" 200 2877
[29/Mar/2019 21:06:04] "GET /serviceRequest/60381/delete/ HTTP/1.1" 200 2820
[29/Mar/2019 21:06:07] "POST /serviceRequest/60381/delete/ HTTP/1.1" 302 0
[29/Mar/2019 21:06:07] "GET /serviceRequest/ HTTP/1.1" 200 190825
[29/Mar/2019 21:06:11] "GET /serviceRequest/ HTTP/1.1" 200 190825
[29/Mar/2019 21:06:17] "GET /serviceRequest/ HTTP/1.1" 200 190825
[29/Mar/2019 21:06:38] "GET /serviceRequest/ HTTP/1.1" 200 190825
[29/Mar/2019 21:06:39] "GET / HTTP/1.1" 200 3998
[29/Mar/2019 21:06:40] "GET /profile/ HTTP/1.1" 200 6910
[29/Mar/2019 21:07:00] "GET /logout/ HTTP/1.1" 200 2299
[29/Mar/2019 21:07:07] "GET /login/ HTTP/1.1" 200 3376
[29/Mar/2019 21:07:11] "POST /login/ HTTP/1.1" 302 0
[29/Mar/2019 21:07:11] "GET / HTTP/1.1" 200 3998
[29/Mar/2019 21:07:13] "GET /serviceRequest/ HTTP/1.1" 200 190825
[29/Mar/2019 21:07:17] "GET /serviceRequest/60379/ HTTP/1.1" 200 2874
[29/Mar/2019 21:07:21] "GET /serviceRequest/ HTTP/1.1" 200 190825
Forbidden (Permission denied): /serviceRequest/60380/
Traceback (most recent call last):
  File "/usr/lib64/python3.6/site-packages/django/core/handlers/exception.py", line 34, in inner
    response = get_response(request)
  File "/usr/lib64/python3.6/site-packages/django/core/handlers/base.py", line 126, in _get_response
    response = self.process_exception_by_middleware(e, request)
  File "/usr/lib64/python3.6/site-packages/django/core/handlers/base.py", line 124, in _get_response
    response = wrapped_callback(request, *callback_args, **callback_kwargs)
  File "/usr/lib64/python3.6/site-packages/django/views/generic/base.py", line 68, in view
    return self.dispatch(request, *args, **kwargs)
  File "/usr/lib64/python3.6/site-packages/django/contrib/auth/mixins.py", line 52, in dispatch
    return super().dispatch(request, *args, **kwargs)
  File "/usr/lib64/python3.6/site-packages/django/contrib/auth/mixins.py", line 108, in dispatch
    return self.handle_no_permission()
  File "/usr/lib64/python3.6/site-packages/django/contrib/auth/mixins.py", line 43, in handle_no_permission
    raise PermissionDenied(self.get_permission_denied_message())
django.core.exceptions.PermissionDenied
[29/Mar/2019 21:07:25] "GET /serviceRequest/60380/ HTTP/1.1" 403 22
[29/Mar/2019 21:08:26] "GET /logout/ HTTP/1.1" 200 2299
[29/Mar/2019 21:08:35] "GET / HTTP/1.1" 200 3908
[29/Mar/2019 21:21:21] "GET / HTTP/1.1" 200 3908
Not Found: /favicon.ico
[29/Mar/2019 21:21:22] "GET /favicon.ico HTTP/1.1" 404 2891
[29/Mar/2019 21:21:24] "GET / HTTP/1.1" 200 3908
[29/Mar/2019 21:21:30] "GET /login/ HTTP/1.1" 200 3376
[29/Mar/2019 21:21:32] "GET /register/ HTTP/1.1" 200 4609
[29/Mar/2019 21:21:34] "GET /login/ HTTP/1.1" 200 3376
[29/Mar/2019 21:21:36] "GET /register/ HTTP/1.1" 200 4609
[29/Mar/2019 21:21:38] "GET /login/ HTTP/1.1" 200 3376
[29/Mar/2019 21:21:55] "POST /login/ HTTP/1.1" 200 3555
[29/Mar/2019 21:21:58] "GET /register/ HTTP/1.1" 200 4609
[29/Mar/2019 21:22:20] "POST /register/ HTTP/1.1" 200 5271
[29/Mar/2019 21:22:48] "POST /register/ HTTP/1.1" 302 0
[29/Mar/2019 21:22:48] "GET /login/ HTTP/1.1" 200 3376
[29/Mar/2019 21:23:09] "POST /login/ HTTP/1.1" 302 0
[29/Mar/2019 21:23:09] "GET / HTTP/1.1" 200 3998
[29/Mar/2019 21:23:19] "GET /serviceRequest/ HTTP/1.1" 200 190825
[29/Mar/2019 21:23:48] "GET /serviceRequest/new/ HTTP/1.1" 200 6222
[29/Mar/2019 21:24:01] "POST /serviceRequest/new/ HTTP/1.1" 302 0
[29/Mar/2019 21:24:01] "GET /serviceRequest/60381/ HTTP/1.1" 200 2878
[29/Mar/2019 21:24:09] "GET /serviceRequest/ HTTP/1.1" 200 190821
[29/Mar/2019 21:24:27] "GET /serviceRequest/new/ HTTP/1.1" 200 6222
[29/Mar/2019 21:24:37] "POST /serviceRequest/new/ HTTP/1.1" 302 0
[29/Mar/2019 21:24:37] "GET /serviceRequest/60382/ HTTP/1.1" 200 2878
[29/Mar/2019 21:24:50] "GET /serviceRequest/60382/update/ HTTP/1.1" 200 6231
[29/Mar/2019 21:24:59] "POST /serviceRequest/60382/update/ HTTP/1.1" 302 0
[29/Mar/2019 21:24:59] "GET /serviceRequest/60382/ HTTP/1.1" 200 2878
[29/Mar/2019 21:25:07] "GET /serviceRequest/ HTTP/1.1" 200 190855
[29/Mar/2019 21:25:16] "GET /serviceRequest/60382/ HTTP/1.1" 200 2878
[29/Mar/2019 21:25:18] "GET /serviceRequest/60382/delete/ HTTP/1.1" 200 2820
[29/Mar/2019 21:25:20] "POST /serviceRequest/60382/delete/ HTTP/1.1" 302 0
[29/Mar/2019 21:25:21] "GET /serviceRequest/ HTTP/1.1" 200 190821
[29/Mar/2019 21:25:25] "GET /serviceRequest/ HTTP/1.1" 200 190821
[29/Mar/2019 21:25:26] "GET /serviceRequest/ HTTP/1.1" 200 190821
[29/Mar/2019 21:25:45] "GET /serviceRequest/60381/ HTTP/1.1" 200 2878
Forbidden (Permission denied): /serviceRequest/60379/
Traceback (most recent call last):
  File "/usr/lib64/python3.6/site-packages/django/core/handlers/exception.py", line 34, in inner
    response = get_response(request)
  File "/usr/lib64/python3.6/site-packages/django/core/handlers/base.py", line 126, in _get_response
    response = self.process_exception_by_middleware(e, request)
  File "/usr/lib64/python3.6/site-packages/django/core/handlers/base.py", line 124, in _get_response
    response = wrapped_callback(request, *callback_args, **callback_kwargs)
  File "/usr/lib64/python3.6/site-packages/django/views/generic/base.py", line 68, in view
    return self.dispatch(request, *args, **kwargs)
  File "/usr/lib64/python3.6/site-packages/django/contrib/auth/mixins.py", line 52, in dispatch
    return super().dispatch(request, *args, **kwargs)
  File "/usr/lib64/python3.6/site-packages/django/contrib/auth/mixins.py", line 108, in dispatch
    return self.handle_no_permission()
  File "/usr/lib64/python3.6/site-packages/django/contrib/auth/mixins.py", line 43, in handle_no_permission
    raise PermissionDenied(self.get_permission_denied_message())
django.core.exceptions.PermissionDenied
[29/Mar/2019 21:25:57] "GET /serviceRequest/60379/ HTTP/1.1" 403 22
[29/Mar/2019 21:26:03] "GET /serviceRequest/60381/ HTTP/1.1" 200 2878
[29/Mar/2019 21:26:11] "GET /serviceRequest/ HTTP/1.1" 200 190821
[29/Mar/2019 21:26:13] "GET /profile/ HTTP/1.1" 200 6912
[29/Mar/2019 21:26:21] "GET /serviceRequest/ HTTP/1.1" 200 190821
[29/Mar/2019 21:26:23] "GET / HTTP/1.1" 200 3998
[29/Mar/2019 21:26:27] "GET /logout/ HTTP/1.1" 200 2299
[29/Mar/2019 21:26:34] "GET /register/ HTTP/1.1" 200 4609
[29/Mar/2019 21:26:37] "GET /login/ HTTP/1.1" 200 3376
[29/Mar/2019 21:26:53] "POST /login/ HTTP/1.1" 302 0
[29/Mar/2019 21:26:53] "GET / HTTP/1.1" 200 3998
[29/Mar/2019 21:26:55] "GET /serviceRequest/ HTTP/1.1" 200 190821
Forbidden (Permission denied): /serviceRequest/60381/
Traceback (most recent call last):
  File "/usr/lib64/python3.6/site-packages/django/core/handlers/exception.py", line 34, in inner
    response = get_response(request)
  File "/usr/lib64/python3.6/site-packages/django/core/handlers/base.py", line 126, in _get_response
    response = self.process_exception_by_middleware(e, request)
  File "/usr/lib64/python3.6/site-packages/django/core/handlers/base.py", line 124, in _get_response
    response = wrapped_callback(request, *callback_args, **callback_kwargs)
  File "/usr/lib64/python3.6/site-packages/django/views/generic/base.py", line 68, in view
    return self.dispatch(request, *args, **kwargs)
  File "/usr/lib64/python3.6/site-packages/django/contrib/auth/mixins.py", line 52, in dispatch
    return super().dispatch(request, *args, **kwargs)
  File "/usr/lib64/python3.6/site-packages/django/contrib/auth/mixins.py", line 108, in dispatch
    return self.handle_no_permission()
  File "/usr/lib64/python3.6/site-packages/django/contrib/auth/mixins.py", line 43, in handle_no_permission
    raise PermissionDenied(self.get_permission_denied_message())
django.core.exceptions.PermissionDenied
[29/Mar/2019 21:26:58] "GET /serviceRequest/60381/ HTTP/1.1" 403 22
[29/Mar/2019 21:27:02] "GET /serviceRequest/60379/ HTTP/1.1" 200 2874
[29/Mar/2019 21:27:06] "GET /serviceRequest/ HTTP/1.1" 200 190821
[29/Mar/2019 21:27:08] "GET /logout/ HTTP/1.1" 200 2299
[29/Mar/2019 21:27:11] "GET /login/ HTTP/1.1" 200 3376
[06/Apr/2019 11:25:50] "GET / HTTP/1.1" 200 3908
[06/Apr/2019 11:25:50] "GET /static/home/main.css HTTP/1.1" 200 1092
[06/Apr/2019 11:25:50] "GET /media/chicago_skyline.jpg HTTP/1.1" 200 167062
Not Found: /favicon.ico
[06/Apr/2019 11:25:50] "GET /favicon.ico HTTP/1.1" 404 2891
[06/Apr/2019 11:25:53] "GET /login/ HTTP/1.1" 200 3376
[06/Apr/2019 11:25:59] "POST /login/ HTTP/1.1" 302 0
[06/Apr/2019 11:25:59] "GET / HTTP/1.1" 200 3998
[06/Apr/2019 11:26:00] "GET /serviceRequest/ HTTP/1.1" 200 190821
[06/Apr/2019 11:27:39] "GET /logout/ HTTP/1.1" 200 2299
[06/Apr/2019 11:27:40] "GET /login/ HTTP/1.1" 200 3376
[06/Apr/2019 11:27:44] "POST /login/ HTTP/1.1" 302 0
[06/Apr/2019 11:27:44] "GET / HTTP/1.1" 200 3998
[06/Apr/2019 11:27:46] "GET /serviceRequest/ HTTP/1.1" 200 190821
[06/Apr/2019 11:27:47] "GET /logout/ HTTP/1.1" 200 2299
[30/Apr/2019 10:04:12] "GET / HTTP/1.1" 200 3908
[30/Apr/2019 10:04:12] "GET /static/home/main.css HTTP/1.1" 200 1092
[30/Apr/2019 10:04:12] "GET /media/chicago_skyline.jpg HTTP/1.1" 200 167062
Not Found: /favicon.ico
[30/Apr/2019 10:04:12] "GET /favicon.ico HTTP/1.1" 404 2891
[30/Apr/2019 10:04:23] "GET / HTTP/1.1" 200 3908
[30/Apr/2019 10:04:26] "GET /login/ HTTP/1.1" 200 3376
[30/Apr/2019 10:04:28] "POST /login/ HTTP/1.1" 302 0
[30/Apr/2019 10:04:28] "GET / HTTP/1.1" 200 3998
[30/Apr/2019 10:04:30] "GET /serviceRequest/ HTTP/1.1" 200 190821
[30/Apr/2019 10:04:36] "GET /serviceRequest/new/ HTTP/1.1" 200 6222
[30/Apr/2019 10:04:39] "GET / HTTP/1.1" 200 3998
[30/Apr/2019 10:04:40] "GET /serviceRequest/ HTTP/1.1" 200 190821
Forbidden (Permission denied): /serviceRequest/60381/
Traceback (most recent call last):
  File "/usr/lib64/python3.6/site-packages/django/core/handlers/exception.py", line 34, in inner
    response = get_response(request)
  File "/usr/lib64/python3.6/site-packages/django/core/handlers/base.py", line 126, in _get_response
    response = self.process_exception_by_middleware(e, request)
  File "/usr/lib64/python3.6/site-packages/django/core/handlers/base.py", line 124, in _get_response
    response = wrapped_callback(request, *callback_args, **callback_kwargs)
  File "/usr/lib64/python3.6/site-packages/django/views/generic/base.py", line 68, in view
    return self.dispatch(request, *args, **kwargs)
  File "/usr/lib64/python3.6/site-packages/django/contrib/auth/mixins.py", line 52, in dispatch
    return super().dispatch(request, *args, **kwargs)
  File "/usr/lib64/python3.6/site-packages/django/contrib/auth/mixins.py", line 108, in dispatch
    return self.handle_no_permission()
  File "/usr/lib64/python3.6/site-packages/django/contrib/auth/mixins.py", line 43, in handle_no_permission
    raise PermissionDenied(self.get_permission_denied_message())
django.core.exceptions.PermissionDenied
[30/Apr/2019 10:04:45] "GET /serviceRequest/60381/ HTTP/1.1" 403 22
[30/Apr/2019 10:04:50] "GET /serviceRequest/60379/ HTTP/1.1" 200 2874
[01/May/2019 07:40:17] "GET / HTTP/1.1" 200 3998
[01/May/2019 07:40:20] "GET /serviceRequest/ HTTP/1.1" 200 190821
[03/May/2019 13:45:00] "GET /serviceRequest/ HTTP/1.1" 200 191539
[03/May/2019 15:11:13] "GET / HTTP/1.1" 200 3908
[03/May/2019 15:11:13] "GET /static/home/main.css HTTP/1.1" 200 1092
[03/May/2019 15:11:13] "GET /media/chicago_skyline.jpg HTTP/1.1" 200 167062
Not Found: /favicon.ico
[03/May/2019 15:11:13] "GET /favicon.ico HTTP/1.1" 404 2891
